Workbook

Sheet 01_MASTER_DATABASE
A1: ID | B1: Nhóm phân khúc | C1: Mã Hệ (System Code) | D1: Hãng Sản Xuất | E1: Quốc Gia | F1: Tiêu Chuẩn | G1: Loại Cửa | H1: Kiểu Mở | I1: Loại Profile | J1: Công Năng | K1: Ứng Dụng Công Trình | L1: Độ Dày Nhôm (mm) | M1: Kính Tương Thích | N1: Kính Tối Đa | O1: Kích Thước Tối Đa (W×H) | P1: Tải Trọng Cánh (kg) | Q1: Chuẩn Phụ Kiện | R1: Gioăng & Keo Lắp Đặt | S1: Bề Mặt & Đặc Tính | T1: Ưu Điểm | U1: Nhược Điểm | V1: Có CAD | W1: Có Shopdrawing | X1: Có Catalogue | Y1: Có HD Lắp Đặt | Z1: Tình Trạng | AA1: Hoàn Thiện (%) | AB1: Link Website | AC1: Link Catalogue PDF | AD1: Link Bản Vẽ CAD | AE1: Link Bản Vẽ CAD
A2: VP-001 | B2: Phổ thông | C2: Việt Pháp 450 | D2: Việt Pháp | E2: Việt Nam | F2: TCVN | G2: Cửa đi | H2: Mở quay | I2: Khung bản sập rời 450mm + Cánh | J2: Nội/Ngoại thất | K2: Nhà cấp 4, nhà phố giá rẻ, nhà xưởng | L2: 1.2 | M2: Kính đơn 5-10mm | N2: 10mm | O2: 1100×2200 | P2: 80 | Q2: Chốt gạt Việt Pháp / Kinlong rãnh 22 | R2: Gioăng EPDM đơn / Silicon Apollo | S2: Sơn tĩnh điện bóng/mờ | T2: Giá thành rẻ, phổ biến rộng rãi, cực kỳ dễ gia công bằng máy dập thường | U2: Bản cánh mỏng chống rung gió yếu, cách âm trung bình | V2: ✓ | W2: ✗ | X2: ✓ | Y2: ✓ | Z2: Hoàn thành | AA2: 85 | AB2: https://vietphapshal.com.vn | AC2: https://nhomkinhdaiphuc.com/catalogue/catalogue-nhom-viet-phap-shal-18.html
A3: VP-002 | B3: Phổ thông | C3: Việt Pháp 4400 | D3: Việt Pháp | E3: Việt Nam | F3: TCVN | G3: Cửa sổ | H3: Mở quay + Mở hất | I3: Khung bản nhỏ 4400mm + Cánh | J3: Nội/Ngoại thất | K3: Cửa sổ phụ nhà dân, vách ngăn phòng | L3: 1.1 | M3: Kính đơn 5-10mm | N3: 10mm | O3: 1000×1400 | P3: 60 | Q3: Khớp chốt Việt Pháp / Kinlong | R3: Gioăng cao su chèn sập / Apollo | S3: Sơn tĩnh điện bóng/mờ | T3: Bản nhôm mỏng nhẹ, chi phí siêu rẻ, dễ gia công nhanh chóng | U3: Độ kín nước và chắn rung gió bão kém | V3: ✓ | W3: ✗ | X3: ✓ | Y3: ✓ | Z3: Hoàn thành | AA3: 85 | AB3: https://vietphapshal.com.vn | AC3: https://nhomkinhdaiphuc.com/catalogue/catalogue-nhom-viet-phap-shal-18.html
A4: VP-003 | B4: Phổ thông | C4: Việt Pháp 2600 | D4: Việt Pháp | E4: Việt Nam | F4: TCVN | G4: Cửa đi + Cửa sổ | H4: Trượt lùa (Sliding) | I4: Khung lùa 2600mm 2 ray | J4: Ngoại thất | K4: Căn hộ chung cư, nhà phố bình dân | L4: 1.1 | M4: Kính đơn 5-10mm | N4: 10mm | O4: 2400×2000 | P4: 70 | Q4: Bánh xe đơn trượt & khóa sập Việt Pháp | R4: Gioăng chèn nỉ mỏng | S4: Sơn tĩnh điện bóng/mờ | T4: Giá thành rẻ, tiết kiệm 100% diện tích không gian đóng mở | U4: Kết cấu mỏng nhẹ, trượt không đầm tay, ray nhôm dễ mòn | V4: ✓ | W4: ✗ | X4: ✓ | Y4: ✓ | Z4: Hoàn thành | AA4: 85 | AB4: https://vietphapshal.com.vn | AC4: https://nhomkinhdaiphuc.com/catalogue/catalogue-nhom-viet-phap-shal-18.html
A5: VP-004 | B5: Tầm trung | C5: Shal 55 | D5: Việt Pháp | E5: Việt Nam | F5: TCVN | G5: Cửa đi + Cửa sổ | H5: Mở quay | I5: Khung phẳng rãnh C 55mm | J5: Nội/Ngoại thất | K5: Nhà phố tầm trung, văn phòng công ty | L5: 1.2 | M5: Kính đơn 6-12mm / Kính hộp | N5: 20mm | O5: 1400×2400 | P5: 100 | Q5: Phụ kiện PMA/Draho rãnh C Châu Âu | R5: Gioăng EPDM kép / Silicon Apollo | S5: Sơn tĩnh điện AkzoNobel | T5: Thiết kế phẳng phiu giống Xingfa hiện đại, khắc phục thẩm mỹ hệ 450 | U5: Phân khúc cạnh tranh khốc liệt với nhôm cỏ trong nước | V5: ✓ | W5: ✓ | X5: ✓ | Y5: ✓ | Z5: Hoàn thành | AA5: 80 | AB5: https://vietphapshal.com.vn | AC5: https://nhomkinhdaiphuc.com/catalogue/catalogue-nhom-viet-phap-shal-18.html
A6: VP-005 | B6: Mặt dựng | C6: Việt Pháp 1100 | D6: Việt Pháp | E6: Việt Nam | F6: TCVN | G6: Vách mặt dựng | H6: Cố định (Fixed Curtain Wall) | I6: Xương mặt dựng Stick 1100 | J6: Ngoại thất | K6: Showroom, tòa nhà văn phòng trung tầng | L6: 1.5 | M6: Kính cường lực 10-12mm / Kính hộp | N6: 24mm | O6: Không giới hạn | P6: 400 | Q6: Ke chịu lực & bulong inox SUS304 | R6: Silicon kết cấu chịu thời tiết | S6: Sơn tĩnh điện bảo hành 10 năm | T6: Thi công lắp dựng ngoài công trường đơn giản, chi phí hợp lý | U6: Độ kín nước phụ thuộc lớn vào chất lượng đi keo tại công trình | V6: ✓ | W6: ✓ | X6: ✓ | Y6: ✓ | Z6: Hoàn thành | AA6: 80 | AB6: https://vietphapshal.com.vn | AC6: https://nhomkinhdaiphuc.com/catalogue/catalogue-nhom-viet-phap-shal-18.html
A7: VP-006 | B7: Cao cấp Premium | C7: Shal Premium | D7: Việt Pháp | E7: Việt Nam | F7: TCVN | G7: Cửa đi + Cửa sổ | H7: Mở quay | I7: Khung rãnh C chuẩn Châu Âu | J7: Ngoại thất | K7: Biệt thự, căn hộ cao cấp ven biển | L7: 1.6 | M7: Kính đơn/hộp 8-32mm | N7: 32mm | O7: 1600×2800 | P7: 150 | Q7: Phụ kiện CMECH / Roto rãnh C Châu Âu | R7: Gioăng EPDM đa khoang / Silicon Dow | S7: Sơn tĩnh điện bảo hành 30 năm | T7: Chất lượng sơn cao cấp bảo hành 30 năm chống muối biển, liên doanh Pháp | U7: Giá thành cao phân khúc biệt thự Luxury | V7: ✓ | W7: ✓ | X7: ✓ | Y7: ✓ | Z7: Hoàn thành | AA7: 80 | AB7: https://vietphapshal.com.vn | AC7: https://nhomkinhdaiphuc.com/catalogue/catalogue-nhom-viet-phap-shal-18.html
A8: PM-001 | B8: Phổ thông Vát cạnh | C8: PMA 55 | D8: PMA | E8: Việt Nam | F8: TCVN | G8: Cửa đi + Cửa sổ | H8: Mở quay + Mở hất | I8: Khung vát cạnh 55mm + Cánh | J8: Nội/Ngoại thất | K8: Nhà phố phổ thông, chung cư, trường học | L8: 1.2 | M8: 5-12mm | N8: 12mm | O8: 1200×2200 | P8: 80 | Q8: Rãnh 22mm đồng bộ | R8: Gioăng EPDM đơn / Silicon Apollo | S8: Sơn tĩnh điện bóng/mờ | T8: Giá thành hợp lý, dễ gia công, linh kiện phổ thông, phù hợp nhà phố | U8: Không phải rãnh C, cách âm thấp hơn hệ cao cấp, không phù hợp cánh quá lớn | V8: ✓ | W8: ✗ | X8: ✓ | Y8: ✓ | Z8: Hoàn thành | AA8: 85 | AB8: https://pma.com.vn | AC8: https://nhomkinhdaiphuc.com/catalogue/catalogue-nhom-pma.html
A9: PM-002 | B9: Cao cấp Platinum | C9: PMA Platinum | D9: PMA | E9: Việt Nam | F9: TCVN | G9: Cửa đi + Cửa sổ | H9: Mở quay | I9: Phào kép nghệ thuật ôm khít khuôn cửa | J9: Nội/Ngoại thất | K9: Biệt thự vườn, biệt thự phố cao cấp | L9: 1.4 | M9: Kính đơn 8-12mm, kính hộp | N9: 24mm | O9: 1600×2800 | P9: 150 | Q9: Rãnh C Châu Âu đồng bộ | R9: Gioăng EPDM đa khoang / Silicon Dow | S9: Sơn tĩnh điện cao cấp AkzoNobel | T9: Cánh phẳng, thiết kế hiện đại, phụ kiện đồng bộ, độ kín nước cao | U9: Chi phí cao, yêu cầu gia công chính xác | V9: ✓ | W9: ✓ | X9: ✓ | Y9: ✓ | Z9: Hoàn thành | AA9: 80 | AB9: https://pma.com.vn | AC9: https://nhomkinhdaiphuc.com/catalogue/catalogue-nhom-pma.html
A10: PM-003 | B10: Rãnh C Classic | C10: PMA Classic 58 | D10: PMA | E10: Việt Nam | F10: TCVN | G10: Cửa đi + Cửa sổ | H10: Mở quay + Mở hất | I10: Khung rãnh C 58mm + Cánh | J10: Nội/Ngoại thất | K10: Căn hộ chung cư cao cấp, văn phòng | L10: 1.3 | M10: Kính đơn/hộp 5-28mm | N10: 28mm | O10: 1400×2600 | P10: 100 | Q10: Rãnh C Châu Âu | R10: Gioăng EPDM đa khoang / Silicon Sika | S10: Sơn tĩnh điện bảo hành 10-15 năm | T10: Tương thích phụ kiện rãnh C Châu Âu, cách âm tốt | U10: Giá trung cấp | V10: ✓ | W10: ✓ | X10: ✓ | Y10: ✓ | Z10: Hoàn thành | AA10: 80 | AB10: https://pma.com.vn | AC10: https://nhomkinhdaiphuc.com/catalogue/catalogue-nhom-pma.html
A11: PM-004 | B11: Rãnh C Classic | C11: PMA 65 | D11: PMA | E11: Việt Nam | F11: TCVN | G11: Cửa đi + Cửa sổ | H11: Mở quay | I11: Khung 65mm + Cánh bản lớn | J11: Ngoại thất | K11: Ứng dụng công nghiệp nặng, kết cấu chịu tải lớn | L11: 2 | M11: Kính đơn/hộp 6-30mm | N11: 30mm | O11: 1500×2600 | P11: 120 | Q11: Rãnh C Châu Âu | R11: Gioăng EPDM đa khoang / Sika | S11: Sơn tĩnh điện bảo hành 10-15 năm | T11: Bản dày chắc khỏe hơn hệ 58, thích ứng tốt cho ứng dụng chịu lực vặn lớn | U11: Trọng lượng lớn hơn, giá nhôm thanh cao hơn | V11: ✓ | W11: ✓ | X11: ✓ | Y11: ✓ | Z11: Hoàn thành | AA11: 80 | AB11: https://pma.com.vn | AC11: https://nhomkinhdaiphuc.com/catalogue/catalogue-nhom-pma.html
A12: PM-005 | B12: Rãnh C Classic | C12: PMA 75 | D12: PMA | E12: Việt Nam | F12: TCVN | G12: Cửa đi | H12: Mở quay | I12: Khung 75mm dày dặn | J12: Ngoại thất | K12: Hệ thống đóng tự động, khu vận chuyển công nghiệp nặng, biệt thự mặt phố chịu gió lớn | L12: 2.5 | M12: Kính hộp đến 32mm | N12: 32mm | O12: 1800×2800 | P12: 150 | Q12: Rãnh C Châu Âu | R12: Gioăng EPDM kép chèn / Silicon Dow | S12: Sơn tĩnh điện bảo hành 15 năm | T12: Khả năng chịu áp lực tải trọng siêu nặng, chịu bão cấp cao ngoại thất | U12: Chi phí đầu tư cao, nặng | V12: ✓ | W12: ✓ | X12: ✓ | Y12: ✓ | Z12: Hoàn thành | AA12: 80 | AB12: https://pma.com.vn | AC12: https://nhomkinhdaiphuc.com/catalogue/catalogue-nhom-pma.html
A13: PM-006 | B13: Trượt lùa Trung cấp | C13: PMA 93 | D13: PMA | E13: Việt Nam | F13: TCVN | G13: Cửa đi | H13: Trượt lùa (Sliding) | I13: Khung lùa 93mm 2 ray/3 ray | J13: Ngoại thất | K13: Căn hộ, văn phòng, nhà phố | L13: 1.4 | M13: Kính đơn/hộp 6-20mm | N13: 20mm | O13: 3000×2400 | P13: 100 | Q13: Bánh xe trượt PMA đồng bộ | R13: Gioăng EPDM kép / Apollo A500 | S13: Sơn tĩnh điện bóng/mờ | T13: Giá bình dân, tối ưu diện tích không gian đóng mở | U13: Độ kín khít cách âm ở mức trung bình | V13: ✓ | W13: ✗ | X13: ✓ | Y13: ✓ | Z13: Hoàn thành | AA13: 80 | AB13: https://pma.com.vn | AC13: https://nhomkinhdaiphuc.com/catalogue/catalogue-nhom-pma.html
... A25: PM-018 | B25: Phổ thông | C25: PMA 72 | D25: PMA | E25: Việt Nam | F25: TCVN | G25: Cửa đi kích thước lớn | H25: Mở quay | I25: Khung bao dày bản lớn | J25: Ngoại thất | K25: Cửa chính mở rộng, cửa ban công khẩu độ lớn biệt thự biển | L25: 2 | M25: Kính cường lực 10-15mm / Kính hộp | N25: 28mm | O25: 1800×2800 | P25: 150 | Q25: Bản lề cối chịu lực & khóa đa điểm | R25: Gioăng đúc xốp kép / Sika | S25: Sơn tĩnh điện AkzoNobel bảo hành 15 năm | T25: Thanh profile cực dày chống rung chấn, vững chãi đóng mở khẩu độ rộng | U25: Cánh nặng nề, chi phí phụ kiện kim khí lớn | V25: ✓ | W25: ✓ | X25: ✓ | Y25: ✓ | Z25: Hoàn thành | AA25: 80 | AB25: https://pma.com.vn | AC25: https://nhomkinhdaiphuc.com/catalogue/catalogue-nhom-pma.html
A26: KG-001 | B26: Xếp trượt Cao cấp | C26: Kogen Slim 50/68 | D26: Kogen | E26: Đức/Việt Nam | F26: EN Châu Âu | G26: Cửa đi | H26: Xếp trượt ẩn bản lề (Hidden Hinge) | I26: Khung mỏng rãnh C ẩn bản lề | J26: Ngoại thất | K26: Biệt thự, penthouse, resort | L26: 1.6 | M26: Kính đơn 8-12mm, kính hộp | N26: 28mm | O26: 5000×2800 | P26: 80 | Q26: Rãnh C Châu Âu đồng bộ Kogen | R26: Gioăng EPDM đa khoang / Silicon Dow | S26: Sơn tĩnh điện hạt mịn chống UV | T26: Bản lề ẩn hoàn toàn khi đóng tạo bề mặt phẳng tinh tế Bauhaus | U26: Gia công cần dưỡng chuyên dụng khoét bản lề ẩn | V26: ✓ | W26: ✓ | X26: ✓ | Y26: ✓ | Z26: Hoàn thành | AA26: 85 | AB26: https://kogen.vn
A27: KG-002 | B27: Slim Ngoại thất Cao cấp | C27: Kogen Slim Lùa | D27: Kogen | E27: Đức/Việt Nam | F27: EN Châu Âu | G27: Cửa đi | H27: Trượt lùa (Sliding Panorama) | I27: Khung cánh siêu mỏng ray inox | J27: Ngoại thất | K27: Biệt thự hướng biển, ban công panorama | L27: 2 | M27: Kính cường lực 10-15mm, kính hộp | N27: 32mm | O27: 6000×3000 | P27: 150 | Q27: Ray inox SUS316L + Bánh xe chịu tải | R27: Gioăng EPDM kép / Dow Corning | S27: Sơn tĩnh điện hạt mịn màu xám ghi | T27: Cánh siêu mảnh tối đa hóa tầm nhìn panorama, ray inox trượt rất nhẹ | U27: Chống gió bão cấp trung bình | V27: ✓ | W27: ✓ | X27: ✓ | Y27: ✓ | Z27: Hoàn thành | AA27: 85 | AB27: https://kogen.vn
A28: KG-003 | B28: Anodized Cao cấp | C28: Kogen 60 Đa khoang | D28: Kogen | E28: Đức/Việt Nam | F28: EN | G28: Cửa đi + Cửa sổ | H28: Mở quay (Casement) | I28: Khung 60mm đa khoang rãnh C | J28: Ngoại thất | K28: Nhà phố hiện đại, biệt thự | L28: 1.6 | M28: Kính đơn/hộp 5-28mm | N28: 28mm | O28: 1400×2600 | P28: 100 | Q28: Rãnh C Châu Âu | R28: Gioăng EPDM đa khoang / Silicon Sika | S28: Sơn tĩnh điện hạt mịn màu ghi | T28: Cấu trúc đa khoang chịu lực cực tốt, cách âm 35dB, rãnh C Châu Âu | U28: Không có cầu cách nhiệt trong hệ này | V28: ✓ | W28: ✓ | X28: ✓ | Y28: ✓ | Z28: Hoàn thành | AA28: 80 | AB28: https://kogen.vn
A29: VR-001 | B29: Anodized Phổ thông | C29: VRA55 | D29: Viralwindow | E29: Việt Nam | F29: TCVN 5826 | G29: Cửa đi + Cửa sổ | H29: Mở quay (Casement) | I29: Khung 55mm + Cánh | J29: Nội/Ngoại thất | K29: Nhà phố, chung cư phổ thông | L29: 1.4 | M29: 5-12mm | N29: 12mm | O29: 1200×2400 | P29: 80 | Q29: Rãnh 22mm | R29: Gioăng EPDM đơn / Keo PU + Silicon | S29: Sơn KCC 20 năm – đa màu | T29: Giá cạnh tranh, đa dạng màu sắc, phổ biến miền Nam | U29: Profile mỏng, không phù hợp cửa rộng lớn | V29: ✓ | W29: ✓ | X29: ✓ | Y29: ✓ | Z29: Hoàn thành | AA29: 90 | AB29: https://viralwindow.com
A30: VR-002 | B30: Anodized Trung cấp | C30: VRA64 | D30: Viralwindow | E30: Việt Nam | F30: TCVN 5826 | G30: Cửa sổ | H30: Trượt lùa (Sliding) | I30: Khung 66×42mm + Cánh 70×28mm | J30: Ngoại thất | K30: Nhà phố, chung cư | L30: 1.3 | M30: 5-10mm | N30: 10mm | O30: 2400×1800 | P30: 80 | Q30: Rãnh 22mm | R30: Gioăng EPDM / Silicon | S30: Sơn tĩnh điện đa màu | T30: Trượt nhẹ, giá tốt | U30: Kín khít trung bình | V30: ✓ | W30: ✗ | X30: ✓ | Y30: ✓ | Z30: Hoàn thành | AA30: 80 | AB30: https://viralwindow.com
A31: VR-003 | B31: Anodized Trung cấp | C31: VRA94 | D31: Viralwindow | E31: Việt Nam | F31: TCVN 5826 | G31: Cửa đi | H31: Trượt lùa (Sliding) | I31: Khung 94×44mm + Cánh 80×34mm | J31: Ngoại thất | K31: Nhà phố, biệt thự | L31: 1.4 | M31: 6.38-30mm | N31: 30mm | O31: 4000×2600 | P31: 150 | Q31: Rãnh C (Euro Groove) | R31: Gioăng EPDM kép / Silicon Dow Corning | S31: Sơn KCC, anodized | T31: Phù hợp cửa lùa rộng, cánh chứa kính hộp | U31: Cần bảo trì bánh xe | V31: ✓ | W31: ✓ | X31: ✓ | Y31: ✓ | Z31: Hoàn thành | AA31: 85 | AB31: https://viralwindow.com
A32: VR-004 | B32: Anodized Cao cấp | C32: VRE65 (Cửa sổ) | D32: Viralwindow | E32: Việt Nam | F32: TCVN | G32: Cửa sổ | H32: Mở quay + Mở hất (Casement/Tilt-Turn) | I32: Khung 65×62mm + Cánh 90×75mm | J32: Ngoại thất | K32: Biệt thự, nhà phố cao cấp | L32: 1.8 | M32: 6.38-37mm | N32: 37mm | O32: 1600×2800 | P32: 150 | Q32: Rãnh C Châu Âu | R32: Gioăng EPDM đa khoang / Dow Corning | S32: Anodized ED, sơn AkzoNobel | T32: Hệ Châu Âu chất lượng cao, phụ kiện CMECH nguyên bộ | U32: Giá cao hơn VRA | V32: ✓ | W32: ✓ | X32: ✓ | Y32: ✓ | Z32: Hoàn thành | AA32: 90 | AB32: https://viralwindow.com
A33: VR-005 | B33: Anodized Cao cấp | C33: VRE65 (Cửa đi) | D33: Viralwindow | E33: Việt Nam | F33: TCVN | G33: Cửa đi | H33: Mở quay (Casement) | I33: Khung 65×70mm + Cánh 97×75mm | J33: Ngoại thất | K33: Biệt thự, nhà phố cao cấp | L33: 1.8 | M33: 6.38-37mm | N33: 37mm | O33: 1400×2800 | P33: 180 | Q33: Rãnh C Châu Âu | R33: Gioăng EPDM đa khoang / Dow Corning | S33: Anodized ED, PVDF | T33: Cứng vững, chứa kính hộp lớn, profile thanh lịch | U33: Giá trung-cao | V33: ✓ | W33: ✓ | X33: ✓ | Y33: ✓ | Z33: Hoàn thành | AA33: 90 | AB33: https://viralwindow.com
A34: VR-006 | B34: Anodized Cao cấp | C34: VRE120 | D34: Viralwindow | E34: Việt Nam | F34: TCVN | G34: Cửa đi | H34: Trượt lùa 2 ray (Sliding) | I34: Khung 120×38mm + Cánh 47×95mm | J34: Ngoại thất | K34: Biệt thự, ban công rộng | L34: 2 | M34: 6.38-34mm | N34: 34mm | O34: 5000×2600 | P34: 200 | Q34: Rãnh C Châu Âu | R34: Gioăng EPDM kép / Silicon Dow Corning | S34: Anodized ED chống muối biển | T34: Trượt lùa 2 ray, cánh rộng, kính hộp lớn, bền bỉ biển | U34: Nặng, cần ray thẳng tuyệt đối | V34: ✓ | W34: ✓ | X34: ✓ | Y34: ✓ | Z34: Hoàn thành | AA34: 85 | AB34: https://viralwindow.com
A35: VR-007 | B35: Anodized Cao cấp | C35: VRE180 | D35: Viralwindow | E35: Việt Nam | F35: TCVN | G35: Cửa đi | H35: Trượt lùa 3 ray (Sliding) | I35: Khung 180mm + Cánh 3 ray | J35: Ngoại thất | K35: Biệt thự, resort cao cấp | L35: 2 | M35: Kính hộp đến 36mm | N35: 36mm | O35: 7000×2800 | P35: 250 | Q35: Rãnh C Châu Âu | R35: Gioăng EPDM 3 lớp / Silicon | S35: Anodized ED | T35: Mở 3 cánh song song, không gian rộng tối đa | U35: Chi phí lắp đặt cao | V35: ✓ | W35: ✓ | X35: ✓ | Y35: ✓ | Z35: Hoàn thành | AA35: 80 | AB35: https://viralwindow.com
A36: VR-008 | B36: Thủy lực Siêu cao cấp | C36: VRE Thủy lực | D36: Viralwindow | E36: Việt Nam | F36: TCVN | G36: Cửa đi | H36: Thủy lực (Hydraulic / Zero Gravity) | I36: Khung siêu nặng + Piston thủy lực | J36: Ngoại thất | K36: Biệt thự siêu sang, villa resort | L36: 2 | M36: Kính hộp 36-50mm / Kính cường lực 15-19mm | N36: 19mm | O36: 3500×3500 | P36: 800 | Q36: Thủy lực Biloba/DICTATOR | R36: Keo SG + EPDM giả thép | S36: Anodized ED vàng 24K, đồng đỏ | T36: Cửa siêu rộng, đóng mở bằng một ngón tay nhờ piston thủy lực | U36: Giá 300tr-1 tỷ/bộ, thi công phức tạp | V36: ✓ | W36: ✓ | X36: ✓ | Y36: ✓ | Z36: Hoàn thành | AA36: 85 | AB36: https://viralwindow.com
A37: VR-009 | B37: Lift & Slide Cao cấp | C37: VRE Lift Slide | D37: Viralwindow | E37: Việt Nam | F37: TCVN | G37: Cửa đi | H37: Trượt nâng (Lift & Slide) | I37: Khung + Cánh + Ray đặc biệt | J37: Ngoại thất | K37: Biệt thự, lối ra sân vườn | L37: 2 | M37: Kính hộp 24-48mm | N37: 19mm | O37: 6000×2800 | P37: 400 | Q37: Roto NT / Siegenia LSS | R37: Gioăng EPDM đa khoang / Dow Corning | S37: Anodized, sơn tĩnh điện | T37: Kín hoàn toàn khi đóng, mở nhẹ dù cánh cực nặng | U37: Giá cao, ray thẳng tuyệt đối | V37: ✓ | W37: ✓ | X37: ✓ | Y37: ✓ | Z37: Hoàn thành | AA37: 80 | AB37: https://viralwindow.com
... A51: CV-013 | B51: Curtain Wall Stick | C51: CCW50 Stick | D51: Civro | E51: Việt Nam | F51: EN 13830 | G51: Vách mặt dựng | H51: Cố định (Fixed – Stick System) | I51: Đố đứng + Đố ngang + Nẹp kính lắp tại chỗ | J51: Ngoại thất – Mặt dựng | K51: Văn phòng, TTTM, khách sạn | L51: 2 | M51: Kính hộp 20-36mm / Kính 3 lớp 44mm | N51: 36mm | O51: Không giới hạn | P51: 500 | Q51: Hệ Stick Châu Âu | R51: Silicon kết cấu SG2000 / Sika | S51: Anodized, PVDF | T51: Linh hoạt thiết kế, thi công từng thanh tại chỗ, dễ sửa chữa | U51: Thi công chậm hơn Unitized | V51: ✓ | W51: ✓ | X51: ✓ | Y51: ✓ | Z51: Đang nghiên cứu | AA51: 65 | AB51: https://civrowindow.com
A52: MP-001 | B52: Anodized Phổ thông | C52: R55 | D52: Maxpro JP | E52: Việt Nam | F52: TCVN / JIS A 4702 | G52: Cửa đi + Cửa sổ | H52: Mở quay (Casement) | I52: Khung 55mm + Cánh | J52: Nội/Ngoại thất | K52: Nhà phố, chung cư, nhà xưởng | L52: 1.4 | M52: 5-10mm | N52: 10mm | O52: 1200×2200 | P52: 80 | Q52: Rãnh C / Rãnh 22 | R52: Gioăng EPDM 2 khoang / Silicon trung tính | S52: Anodized ED chuẩn Nhật JIS H8602 – bền 40 năm | T52: Anodize ED bền màu 40 năm, phụ kiện CMECH nguyên bộ, tỷ lệ bản rộng Nhật Bản tinh tế | U52: Phân phối ít ở miền Bắc | V52: ✓ | W52: ✓ | X52: ✓ | Y52: ✓ | Z52: Hoàn thành | AA52: 85 | AB52: https://maxprojp.com.vn | AC52: https://nhomkinhdaiphuc.com/catalogue/catalogue-nhom-maxpro-7.html
A53: MP-002 | B53: Anodized Trung cao cấp | C53: R65 | D53: Maxpro JP | E53: Việt Nam | F53: TCVN / JIS A 4702 | G53: Cửa đi + Cửa sổ | H53: Mở quay + Mở hất (Casement + Awning) | I53: Khung 65mm + Cánh | J53: Ngoại thất | K53: Biệt thự, nhà phố cao cấp, văn phòng hạng B | L53: 1.6 | M53: 5-12mm / Kính hộp 20-28mm | N53: 12mm | O53: 1600×2800 | P53: 150 | Q53: Rãnh C Euro Groove | R53: Gioăng EPDM đa khoang / Silicon Sika 11FC | S53: Anodized ED Nhật bền màu, sơn PVDF | T53: Hệ phụ kiện Nhật tích hợp sẵn, profile thanh lịch hơn hệ Trung Quốc | U53: Giá cao hơn hàng TQ 20-30% | V53: ✓ | W53: ✓ | X53: ✓ | Y53: ✓ | Z53: Hoàn thành | AA53: 85 | AB53: https://maxprojp.com.vn | AC53: https://nhomkinhdaiphuc.com/catalogue/catalogue-nhom-maxpro-7.html
A54: MP-003 | B54: Anodized Siêu cao cấp | C54: R65 Plus | D54: Maxpro JP | E54: Việt Nam | F54: TCVN / JIS | G54: Cửa đi + Cửa sổ | H54: Mở quay + Mở hất (Casement + Awning) | I54: Khung 65mm Plus + thêm gioăng giữa | J54: Ngoại thất | K54: Biệt thự cao cấp | L54: 1.6 | M54: 5-20mm / Kính hộp | N54: 20mm | O54: 1600×2800 | P54: 150 | Q54: Rãnh C Châu Âu | R54: Gioăng EPDM 3 khoang (cải tiến) / Silicon | S54: Anodized ED Nhật | T54: Cải tiến thêm gioăng giữa, kín khít hơn R65 thường | U54: Giá cao hơn R65 | V54: ✓ | W54: ✓ | X54: ✓ | Y54: ✓ | Z54: Hoàn thành | AA54: 82 | AB54: https://maxprojp.com.vn | AC54: https://nhomkinhdaiphuc.com/catalogue/catalogue-nhom-maxpro-7.html
A55: MP-004 | B55: Tân cổ điển Cao cấp | C55: R70 | D55: Maxpro JP | E55: Việt Nam | F55: TCVN / JIS | G55: Cửa đi | H55: Mở quay – Vát cạnh tân cổ điển | I55: Khung 70mm vát cạnh mạnh | J55: Ngoại thất | K55: Biệt thự tân cổ điển | L55: 2 | M55: 5-15mm | N55: 15mm | O55: 1400×2800 | P55: 180 | Q55: Rãnh C Châu Âu | R55: Gioăng EPDM / Silicon | S55: Anodized ED, sơn gold champagne, vân gỗ | T55: Profile vát cạnh đặc trưng tân cổ điển, không trùng hệ khác | U55: Không phù hợp phong cách hiện đại | V55: ✓ | W55: ✓ | X55: ✓ | Y55: ✓ | Z55: Hoàn thành | AA55: 80 | AB55: https://maxprojp.com.vn | AC55: https://nhomkinhdaiphuc.com/catalogue/catalogue-nhom-maxpro-7.html
A56: MP-005 | B56: Tân cổ điển Siêu cao cấp | C56: R83 | D56: Maxpro JP | E56: Việt Nam | F56: TCVN / JIS | G56: Cửa đi + Cửa vòm + Cửa sổ | H56: Mở quay + Mở hất | I56: Khung 83mm vát cạnh + Cánh vòm cung | J56: Ngoại thất | K56: Biệt thự cổ điển Pháp, biệt thự vòm | L56: 1.8 | M56: 5-25mm | N56: 25mm | O56: 2000×3500 | P56: 200 | Q56: Rãnh C Châu Âu | R56: Gioăng EPDM đa khoang / Dow Corning | S56: Anodized, sơn vàng gold, vân gỗ | T56: Hệ tân cổ điển đỉnh cao, làm được cửa vòm cung phức tạp | U56: Chỉ phù hợp phong cách cổ điển | V56: ✓ | W56: ✓ | X56: ✓ | Y56: ✓ | Z56: Hoàn thành | AA56: 80 | AB56: https://maxprojp.com.vn | AC56: https://nhomkinhdaiphuc.com/catalogue/catalogue-nhom-maxpro-7.html
A57: MP-006 | B57: Thủy lực Siêu cao cấp | C57: R200 Thủy lực | D57: Maxpro JP | E57: Việt Nam | F57: TCVN | G57: Cửa đi | H57: Thủy lực (Hydraulic Door) | I57: Khung 200mm siêu nặng + Hệ thủy lực | J57: Ngoại thất | K57: Biệt thự siêu cao cấp, cửa đại sảnh | L57: 2 | M57: Kính cường lực 15-22mm | N57: 22mm | O57: 3000×3500 | P57: 800 | Q57: Thủy lực đặc chủng Dorma/Biloba | R57: Keo silicon kết cấu / EPDM giả thép | S57: Anodized ED, sơn RAL đặc chủng | T57: Bản cánh 200mm siêu rộng, đóng mở êm tuyệt đối bằng hệ thủy lực cân bằng | U57: Giá rất cao, gia cố nền sàn đặc biệt | V57: ✓ | W57: ✓ | X57: ✓ | Y57: ✓ | Z57: Hoàn thành | AA57: 75 | AB57: https://maxprojp.com.vn | AC57: https://nhomkinhdaiphuc.com/catalogue/catalogue-nhom-maxpro-7.html
A58: MP-007 | B58: Trượt lùa Trung cấp | C58: SW55 | D58: Maxpro JP | E58: Việt Nam | F58: TCVN | G58: Cửa sổ | H58: Trượt lùa (Sliding Window) | I58: Khung SW 55mm + Cánh trượt | J58: Ngoại thất | K58: Nhà phố phổ thông | L58: 1.4 | M58: 5-10mm | N58: 10mm | O58: 2400×1800 | P58: 80 | Q58: Rãnh 22 / Rãnh C | R58: Gioăng EPDM / Silicon | S58: Anodized ED Nhật, sơn tĩnh điện | T58: Trượt êm, giá cạnh tranh, Anodized ED bền 40 năm | U58: Kín khít trung bình | V58: ✓ | W58: ✗ | X58: ✓ | Y58: ✓ | Z58: Hoàn thành | AA58: 75 | AB58: https://maxprojp.com.vn | AC58: https://nhomkinhdaiphuc.com/catalogue/catalogue-nhom-maxpro-7.html
A59: MP-008 | B59: Trượt lùa Cao cấp | C59: SD83 | D59: Maxpro JP | E59: Việt Nam | F59: TCVN | G59: Cửa đi | H59: Trượt lùa phẳng (Sliding Door) | I59: Khung SD 83mm + Cánh | J59: Ngoại thất | K59: Nhà phố, biệt thự | L59: 1.6 | M59: 8-12mm / Kính hộp 20-28mm | N59: 12mm | O59: 4000×2400 | P59: 150 | Q59: Ray inox SUS304 | R59: Gioăng EPDM / Dow Corning | S59: Anodized ED Nhật | T59: Trượt êm hệ Nhật, Anodized ED bền 40 năm | U59: Kín khít kém hơn Lift Slide | V59: ✓ | W59: ✓ | X59: ✓ | Y59: ✓ | Z59: Hoàn thành | AA59: 80 | AB59: https://maxprojp.com.vn | AC59: https://nhomkinhdaiphuc.com/catalogue/catalogue-nhom-maxpro-7.html
A60: MP-009 | B60: Trượt lùa Siêu cao cấp | C60: SD115 Chống bão | D60: Maxpro JP | E60: Việt Nam | F60: TCVN | G60: Cửa đi | H60: Trượt lùa chịu bão (Storm Resistant Sliding) | I60: Khung SD 115mm + Cánh siêu dày | J60: Ngoại thất – Biển | K60: Biệt thự biển, resort duyên hải chịu bão cấp 14 | L60: 2.5 | M60: Kính hộp chống bão 24-36mm | N60: 15mm | O60: 5000×2600 | P60: 300 | Q60: Ray inox SUS316L chống muối biển | R60: Gioăng EPDM cầu cách nhiệt / Silicon Dow Corning | S60: Anodized ED chống muối biển AS 1734-5 | T60: Chịu gió bão cấp 14, kín nước EN 12208 Cls 9A, chịu muối biển lâu dài | U60: Giá rất cao, nặng | V60: ✓ | W60: ✓ | X60: ✓ | Y60: ✓ | Z60: Hoàn thành | AA60: 80 | AB60: https://maxprojp.com.vn | AC60: https://nhomkinhdaiphuc.com/catalogue/catalogue-nhom-maxpro-7.html
A61: MP-010 | B61: Xếp trượt Cao cấp | C61: SFD80 | D61: Maxpro JP | E61: Việt Nam | F61: TCVN | G61: Cửa đi | H61: Xếp trượt (Folding Sliding Door) | I61: Cánh xếp gấp 80mm + Bản lề xếp | J61: Ngoại thất | K61: Biệt thự, nhà hàng, không gian mở | L61: 1.8 | M61: Kính cường lực 8-12mm | N61: 12mm | O61: 5000×2800 | P61: 40 | Q61: OPK Bi-fold / Roto Fold | R61: Gioăng EPDM / Silicon | S61: Anodized ED Nhật, sơn tĩnh điện | T61: Mở toàn bộ không gian Nhật, bền bỉ phụ kiện Nhật | U61: Kín khít thấp nhất trong hệ lùa | V61: ✓ | W61: ✓ | X61: ✓ | Y61: ✓ | Z61: Đang nghiên cứu | AA61: 65 | AB61: https://maxprojp.com.vn | AC61: https://nhomkinhdaiphuc.com/catalogue/catalogue-nhom-maxpro-7.html
A62: MP-011 | B62: Lam chắn nắng | C62: GW65 | D62: Maxpro JP | E62: Việt Nam | F62: TCVN | G62: Lam chắn nắng | H62: Cố định / Xoay (Fixed / Motorized Louvres) | I62: Profile lam 65mm xoay | J62: Ngoại thất | K62: Mặt ngoài công trình, ban công, sân thượng | L62: 1.6 | M62: Không dùng kính | N62: N/A | O62: Không giới hạn | P62: 50 | Q62: Hệ xoay cơ / Mô tơ tự động | R62: Không cần keo | S62: Anodized, sơn tĩnh điện chịu UV | T62: Chắn nắng điều tiết ánh sáng, thẩm mỹ hiện đại mặt công trình | U62: Cần bảo trì mô tơ định kỳ | V62: ✓ | W62: ✗ | X62: ✓ | Y62: ✓ | Z62: Đang nghiên cứu | AA62: 55 | AB62: https://maxprojp.com.vn | AC62: https://nhomkinhdaiphuc.com/catalogue/catalogue-nhom-maxpro-7.html
A63: SC-001 | B63: Anodized Cao cấp | C63: Soco 65 | D63: Soco | E63: Việt Nam | F63: EN Châu Âu | G63: Cửa đi + Cửa sổ | H63: Mở quay + Mở hất (Casement + Awning) | I63: Khung 65mm rãnh C | J63: Ngoại thất | K63: Biệt thự, nhà phố cao cấp | L63: 1.6 | M63: 5-12mm / Kính hộp 20-28mm | N63: 12mm | O63: 1600×2800 | P63: 150 | Q63: Rãnh C Châu Âu – Cmech/Sigico/Bogo | R63: Gioăng EPDM đa khoang / Silicon | S63: Anodized vàng ánh kim Champagne đặc trưng Soco | T63: Màu Champagne đặc trưng sang trọng, rãnh C Châu Âu đầy đủ phụ kiện | U63: Ít phân phối ngoài miền Nam | V63: ✓ | W63: ✓ | X63: ✓ | Y63: ✓ | Z63: Hoàn thành | AA63: 80 | AB63: https://nhomsocowindow.com
A64: SC-002 | B64: Trượt lùa Trung cấp | C64: Soco 94 | D64: Soco | E64: Việt Nam | F64: EN Châu Âu | G64: Cửa đi | H64: Trượt lùa 2 ray (Sliding) | I64: Khung 94mm + Ray inox | J64: Ngoại thất | K64: Nhà phố, biệt thự | L64: 1.6 | M64: 6-12mm | N64: 12mm | O64: 4000×2600 | P64: 150 | Q64: Ray inox SUS304 | R64: Gioăng EPDM / Silicon | S64: Anodized Champagne, sơn tĩnh điện | T64: Trượt êm ray inox, màu Champagne sang trọng | U64: Kín khít trung bình | V64: ✓ | W64: ✓ | X64: ✓ | Y64: ✓ | Z64: Hoàn thành | AA64: 78 | AB64: https://nhomsocowindow.com
...

Sheet 02_TỔNG QUAN HỆ NHÔM
A1: BẢNG TỔNG QUAN SỐ LƯỢNG HỆ THEO TỪNG HÃNG SẢN XUẤT
A4: Hãng | B4: Số Hệ | C4: Cửa Đi | D4: Cửa Sổ | E4: Hệ Slim | F4: Hệ Thermal | G4: Vách / Mặt Dựng | H4: Lan Can
A5: Civro | B5: =COUNTIF('01_MASTER_DATABASE'!$D$2:$D$500, A5) | C5: =COUNTIFS('01_MASTER_DATABASE'!$D$2:$D$500, A5, '01_MASTER_DATABASE'!$G$2:$G$500, "*Cửa đi*") | D5: =COUNTIFS('01_MASTER_DATABASE'!$D$2:$D$500, A5, '01_MASTER_DATABASE'!$G$2:$G$500, "*Cửa sổ*") | E5: =COUNTIFS('01_MASTER_DATABASE'!$D$2:$D$500, A5, '01_MASTER_DATABASE'!$B$2:$B$500, "*Slim*") | F5: =COUNTIFS('01_MASTER_DATABASE'!$D$2:$D$500, A5, '01_MASTER_DATABASE'!$B$2:$B$500, "*Thermal*") + COUNTIFS('01_MASTER_DATABASE'!$D$2:$D$500, A5, '01_MASTER_DATABASE'!$B$2:$B$500, "*cầu*") | G5: =COUNTIFS('01_MASTER_DATABASE'!$D$2:$D$500, A5, '01_MASTER_DATABASE'!$G$2:$G$500, "*mặt dựng*") + COUNTIFS('01_MASTER_DATABASE'!$D$2:$D$500, A5, '01_MASTER_DATABASE'!$G$2:$G$500, "*vách*") | H5: =COUNTIFS('01_MASTER_DATABASE'!$D$2:$D$500, A5, '01_MASTER_DATABASE'!$G$2:$G$500, "*lan can*")
A6: Civro/Maxpro/Soco | B6: =COUNTIF('01_MASTER_DATABASE'!$D$2:$D$500, A6) | C6: =COUNTIFS('01_MASTER_DATABASE'!$D$2:$D$500, A6, '01_MASTER_DATABASE'!$G$2:$G$500, "*Cửa đi*") | D6: =COUNTIFS('01_MASTER_DATABASE'!$D$2:$D$500, A6, '01_MASTER_DATABASE'!$G$2:$G$500, "*Cửa sổ*") | E6: =COUNTIFS('01_MASTER_DATABASE'!$D$2:$D$500, A6, '01_MASTER_DATABASE'!$B$2:$B$500, "*Slim*") | F6: =COUNTIFS('01_MASTER_DATABASE'!$D$2:$D$500, A6, '01_MASTER_DATABASE'!$B$2:$B$500, "*Thermal*") + COUNTIFS('01_MASTER_DATABASE'!$D$2:$D$500, A6, '01_MASTER_DATABASE'!$B$2:$B$500, "*cầu*") | G6: =COUNTIFS('01_MASTER_DATABASE'!$D$2:$D$500, A6, '01_MASTER_DATABASE'!$G$2:$G$500, "*mặt dựng*") + COUNTIFS('01_MASTER_DATABASE'!$D$2:$D$500, A6, '01_MASTER_DATABASE'!$G$2:$G$500, "*vách*") | H6: =COUNTIFS('01_MASTER_DATABASE'!$D$2:$D$500, A6, '01_MASTER_DATABASE'!$G$2:$G$500, "*lan can*")
A7: Civro/Owin/Local | B7: =COUNTIF('01_MASTER_DATABASE'!$D$2:$D$500, A7) | C7: =COUNTIFS('01_MASTER_DATABASE'!$D$2:$D$500, A7, '01_MASTER_DATABASE'!$G$2:$G$500, "*Cửa đi*") | D7: =COUNTIFS('01_MASTER_DATABASE'!$D$2:$D$500, A7, '01_MASTER_DATABASE'!$G$2:$G$500, "*Cửa sổ*") | E7: =COUNTIFS('01_MASTER_DATABASE'!$D$2:$D$500, A7, '01_MASTER_DATABASE'!$B$2:$B$500, "*Slim*") | F7: =COUNTIFS('01_MASTER_DATABASE'!$D$2:$D$500, A7, '01_MASTER_DATABASE'!$B$2:$B$500, "*Thermal*") + COUNTIFS('01_MASTER_DATABASE'!$D$2:$D$500, A7, '01_MASTER_DATABASE'!$B$2:$B$500, "*cầu*") | G7: =COUNTIFS('01_MASTER_DATABASE'!$D$2:$D$500, A7, '01_MASTER_DATABASE'!$G$2:$G$500, "*mặt dựng*") + COUNTIFS('01_MASTER_DATABASE'!$D$2:$D$500, A7, '01_MASTER_DATABASE'!$G$2:$G$500, "*vách*") | H7: =COUNTIFS('01_MASTER_DATABASE'!$D$2:$D$500, A7, '01_MASTER_DATABASE'!$G$2:$G$500, "*lan can*")
A8: Civro/PAG/Schüco | B8: =COUNTIF('01_MASTER_DATABASE'!$D$2:$D$500, A8) | C8: =COUNTIFS('01_MASTER_DATABASE'!$D$2:$D$500, A8, '01_MASTER_DATABASE'!$G$2:$G$500, "*Cửa đi*") | D8: =COUNTIFS('01_MASTER_DATABASE'!$D$2:$D$500, A8, '01_MASTER_DATABASE'!$G$2:$G$500, "*Cửa sổ*") | E8: =COUNTIFS('01_MASTER_DATABASE'!$D$2:$D$500, A8, '01_MASTER_DATABASE'!$B$2:$B$500, "*Slim*") | F8: =COUNTIFS('01_MASTER_DATABASE'!$D$2:$D$500, A8, '01_MASTER_DATABASE'!$B$2:$B$500, "*Thermal*") + COUNTIFS('01_MASTER_DATABASE'!$D$2:$D$500, A8, '01_MASTER_DATABASE'!$B$2:$B$500, "*cầu*") | G8: =COUNTIFS('01_MASTER_DATABASE'!$D$2:$D$500, A8, '01_MASTER_DATABASE'!$G$2:$G$500, "*mặt dựng*") + COUNTIFS('01_MASTER_DATABASE'!$D$2:$D$500, A8, '01_MASTER_DATABASE'!$G$2:$G$500, "*vách*") | H8: =COUNTIFS('01_MASTER_DATABASE'!$D$2:$D$500, A8, '01_MASTER_DATABASE'!$G$2:$G$500, "*lan can*")
A9: Các hãng | B9: =COUNTIF('01_MASTER_DATABASE'!$D$2:$D$500, A9) | C9: =COUNTIFS('01_MASTER_DATABASE'!$D$2:$D$500, A9, '01_MASTER_DATABASE'!$G$2:$G$500, "*Cửa đi*") | D9: =COUNTIFS('01_MASTER_DATABASE'!$D$2:$D$500, A9, '01_MASTER_DATABASE'!$G$2:$G$500, "*Cửa sổ*") | E9: =COUNTIFS('01_MASTER_DATABASE'!$D$2:$D$500, A9, '01_MASTER_DATABASE'!$B$2:$B$500, "*Slim*") | F9: =COUNTIFS('01_MASTER_DATABASE'!$D$2:$D$500, A9, '01_MASTER_DATABASE'!$B$2:$B$500, "*Thermal*") + COUNTIFS('01_MASTER_DATABASE'!$D$2:$D$500, A9, '01_MASTER_DATABASE'!$B$2:$B$500, "*cầu*") | G9: =COUNTIFS('01_MASTER_DATABASE'!$D$2:$D$500, A9, '01_MASTER_DATABASE'!$G$2:$G$500, "*mặt dựng*") + COUNTIFS('01_MASTER_DATABASE'!$D$2:$D$500, A9, '01_MASTER_DATABASE'!$G$2:$G$500, "*vách*") | H9: =COUNTIFS('01_MASTER_DATABASE'!$D$2:$D$500, A9, '01_MASTER_DATABASE'!$G$2:$G$500, "*lan can*")
A10: Dorma/Besam/Local | B10: =COUNTIF('01_MASTER_DATABASE'!$D$2:$D$500, A10) | C10: =COUNTIFS('01_MASTER_DATABASE'!$D$2:$D$500, A10, '01_MASTER_DATABASE'!$G$2:$G$500, "*Cửa đi*") | D10: =COUNTIFS('01_MASTER_DATABASE'!$D$2:$D$500, A10, '01_MASTER_DATABASE'!$G$2:$G$500, "*Cửa sổ*") | E10: =COUNTIFS('01_MASTER_DATABASE'!$D$2:$D$500, A10, '01_MASTER_DATABASE'!$B$2:$B$500, "*Slim*") | F10: =COUNTIFS('01_MASTER_DATABASE'!$D$2:$D$500, A10, '01_MASTER_DATABASE'!$B$2:$B$500, "*Thermal*") + COUNTIFS('01_MASTER_DATABASE'!$D$2:$D$500, A10, '01_MASTER_DATABASE'!$B$2:$B$500, "*cầu*") | G10: =COUNTIFS('01_MASTER_DATABASE'!$D$2:$D$500, A10, '01_MASTER_DATABASE'!$G$2:$G$500, "*mặt dựng*") + COUNTIFS('01_MASTER_DATABASE'!$D$2:$D$500, A10, '01_MASTER_DATABASE'!$G$2:$G$500, "*vách*") | H10: =COUNTIFS('01_MASTER_DATABASE'!$D$2:$D$500, A10, '01_MASTER_DATABASE'!$G$2:$G$500, "*lan can*")
A11: EuroVN | B11: =COUNTIF('01_MASTER_DATABASE'!$D$2:$D$500, A11) | C11: =COUNTIFS('01_MASTER_DATABASE'!$D$2:$D$500, A11, '01_MASTER_DATABASE'!$G$2:$G$500, "*Cửa đi*") | D11: =COUNTIFS('01_MASTER_DATABASE'!$D$2:$D$500, A11, '01_MASTER_DATABASE'!$G$2:$G$500, "*Cửa sổ*") | E11: =COUNTIFS('01_MASTER_DATABASE'!$D$2:$D$500, A11, '01_MASTER_DATABASE'!$B$2:$B$500, "*Slim*") | F11: =COUNTIFS('01_MASTER_DATABASE'!$D$2:$D$500, A11, '01_MASTER_DATABASE'!$B$2:$B$500, "*Thermal*") + COUNTIFS('01_MASTER_DATABASE'!$D$2:$D$500, A11, '01_MASTER_DATABASE'!$B$2:$B$500, "*cầu*") | G11: =COUNTIFS('01_MASTER_DATABASE'!$D$2:$D$500, A11, '01_MASTER_DATABASE'!$G$2:$G$500, "*mặt dựng*") + COUNTIFS('01_MASTER_DATABASE'!$D$2:$D$500, A11, '01_MASTER_DATABASE'!$G$2:$G$500, "*vách*") | H11: =COUNTIFS('01_MASTER_DATABASE'!$D$2:$D$500, A11, '01_MASTER_DATABASE'!$G$2:$G$500, "*lan can*")
A12: Eurowindow | B12: =COUNTIF('01_MASTER_DATABASE'!$D$2:$D$500, A12) | C12: =COUNTIFS('01_MASTER_DATABASE'!$D$2:$D$500, A12, '01_MASTER_DATABASE'!$G$2:$G$500, "*Cửa đi*") | D12: =COUNTIFS('01_MASTER_DATABASE'!$D$2:$D$500, A12, '01_MASTER_DATABASE'!$G$2:$G$500, "*Cửa sổ*") | E12: =COUNTIFS('01_MASTER_DATABASE'!$D$2:$D$500, A12, '01_MASTER_DATABASE'!$B$2:$B$500, "*Slim*") | F12: =COUNTIFS('01_MASTER_DATABASE'!$D$2:$D$500, A12, '01_MASTER_DATABASE'!$B$2:$B$500, "*Thermal*") + COUNTIFS('01_MASTER_DATABASE'!$D$2:$D$500, A12, '01_MASTER_DATABASE'!$B$2:$B$500, "*cầu*") | G12: =COUNTIFS('01_MASTER_DATABASE'!$D$2:$D$500, A12, '01_MASTER_DATABASE'!$G$2:$G$500, "*mặt dựng*") + COUNTIFS('01_MASTER_DATABASE'!$D$2:$D$500, A12, '01_MASTER_DATABASE'!$G$2:$G$500, "*vách*") | H12: =COUNTIFS('01_MASTER_DATABASE'!$D$2:$D$500, A12, '01_MASTER_DATABASE'!$G$2:$G$500, "*lan can*")
A13: Hondalex | B13: =COUNTIF('01_MASTER_DATABASE'!$D$2:$D$500, A13) | C13: =COUNTIFS('01_MASTER_DATABASE'!$D$2:$D$500, A13, '01_MASTER_DATABASE'!$G$2:$G$500, "*Cửa đi*") | D13: =COUNTIFS('01_MASTER_DATABASE'!$D$2:$D$500, A13, '01_MASTER_DATABASE'!$G$2:$G$500, "*Cửa sổ*") | E13: =COUNTIFS('01_MASTER_DATABASE'!$D$2:$D$500, A13, '01_MASTER_DATABASE'!$B$2:$B$500, "*Slim*") | F13: =COUNTIFS('01_MASTER_DATABASE'!$D$2:$D$500, A13, '01_MASTER_DATABASE'!$B$2:$B$500, "*Thermal*") + COUNTIFS('01_MASTER_DATABASE'!$D$2:$D$500, A13, '01_MASTER_DATABASE'!$B$2:$B$500, "*cầu*") | G13: =COUNTIFS('01_MASTER_DATABASE'!$D$2:$D$500, A13, '01_MASTER_DATABASE'!$G$2:$G$500, "*mặt dựng*") + COUNTIFS('01_MASTER_DATABASE'!$D$2:$D$500, A13, '01_MASTER_DATABASE'!$G$2:$G$500, "*vách*") | H13: =COUNTIFS('01_MASTER_DATABASE'!$D$2:$D$500, A13, '01_MASTER_DATABASE'!$G$2:$G$500, "*lan can*")
A14: Hệ PCCC | B14: =COUNTIF('01_MASTER_DATABASE'!$D$2:$D$500, A14) | C14: =COUNTIFS('01_MASTER_DATABASE'!$D$2:$D$500, A14, '01_MASTER_DATABASE'!$G$2:$G$500, "*Cửa đi*") | D14: =COUNTIFS('01_MASTER_DATABASE'!$D$2:$D$500, A14, '01_MASTER_DATABASE'!$G$2:$G$500, "*Cửa sổ*") | E14: =COUNTIFS('01_MASTER_DATABASE'!$D$2:$D$500, A14, '01_MASTER_DATABASE'!$B$2:$B$500, "*Slim*") | F14: =COUNTIFS('01_MASTER_DATABASE'!$D$2:$D$500, A14, '01_MASTER_DATABASE'!$B$2:$B$500, "*Thermal*") + COUNTIFS('01_MASTER_DATABASE'!$D$2:$D$500, A14, '01_MASTER_DATABASE'!$B$2:$B$500, "*cầu*") | G14: =COUNTIFS('01_MASTER_DATABASE'!$D$2:$D$500, A14, '01_MASTER_DATABASE'!$G$2:$G$500, "*mặt dựng*") + COUNTIFS('01_MASTER_DATABASE'!$D$2:$D$500, A14, '01_MASTER_DATABASE'!$G$2:$G$500, "*vách*") | H14: =COUNTIFS('01_MASTER_DATABASE'!$D$2:$D$500, A14, '01_MASTER_DATABASE'!$G$2:$G$500, "*lan can*")
A15: Hệ Smart | B15: =COUNTIF('01_MASTER_DATABASE'!$D$2:$D$500, A15) | C15: =COUNTIFS('01_MASTER_DATABASE'!$D$2:$D$500, A15, '01_MASTER_DATABASE'!$G$2:$G$500, "*Cửa đi*") | D15: =COUNTIFS('01_MASTER_DATABASE'!$D$2:$D$500, A15, '01_MASTER_DATABASE'!$G$2:$G$500, "*Cửa sổ*") | E15: =COUNTIFS('01_MASTER_DATABASE'!$D$2:$D$500, A15, '01_MASTER_DATABASE'!$B$2:$B$500, "*Slim*") | F15: =COUNTIFS('01_MASTER_DATABASE'!$D$2:$D$500, A15, '01_MASTER_DATABASE'!$B$2:$B$500, "*Thermal*") + COUNTIFS('01_MASTER_DATABASE'!$D$2:$D$500, A15, '01_MASTER_DATABASE'!$B$2:$B$500, "*cầu*") | G15: =COUNTIFS('01_MASTER_DATABASE'!$D$2:$D$500, A15, '01_MASTER_DATABASE'!$G$2:$G$500, "*mặt dựng*") + COUNTIFS('01_MASTER_DATABASE'!$D$2:$D$500, A15, '01_MASTER_DATABASE'!$G$2:$G$500, "*vách*") | H15: =COUNTIFS('01_MASTER_DATABASE'!$D$2:$D$500, A15, '01_MASTER_DATABASE'!$G$2:$G$500, "*lan can*")
A16: Hệ chuyên dụng | B16: =COUNTIF('01_MASTER_DATABASE'!$D$2:$D$500, A16) | C16: =COUNTIFS('01_MASTER_DATABASE'!$D$2:$D$500, A16, '01_MASTER_DATABASE'!$G$2:$G$500, "*Cửa đi*") | D16: =COUNTIFS('01_MASTER_DATABASE'!$D$2:$D$500, A16, '01_MASTER_DATABASE'!$G$2:$G$500, "*Cửa sổ*") | E16: =COUNTIFS('01_MASTER_DATABASE'!$D$2:$D$500, A16, '01_MASTER_DATABASE'!$B$2:$B$500, "*Slim*") | F16: =COUNTIFS('01_MASTER_DATABASE'!$D$2:$D$500, A16, '01_MASTER_DATABASE'!$B$2:$B$500, "*Thermal*") + COUNTIFS('01_MASTER_DATABASE'!$D$2:$D$500, A16, '01_MASTER_DATABASE'!$B$2:$B$500, "*cầu*") | G16: =COUNTIFS('01_MASTER_DATABASE'!$D$2:$D$500, A16, '01_MASTER_DATABASE'!$G$2:$G$500, "*mặt dựng*") + COUNTIFS('01_MASTER_DATABASE'!$D$2:$D$500, A16, '01_MASTER_DATABASE'!$G$2:$G$500, "*vách*") | H16: =COUNTIFS('01_MASTER_DATABASE'!$D$2:$D$500, A16, '01_MASTER_DATABASE'!$G$2:$G$500, "*lan can*")
... A43: Yangli | B43: =COUNTIF('01_MASTER_DATABASE'!$D$2:$D$500, A43) | C43: =COUNTIFS('01_MASTER_DATABASE'!$D$2:$D$500, A43, '01_MASTER_DATABASE'!$G$2:$G$500, "*Cửa đi*") | D43: =COUNTIFS('01_MASTER_DATABASE'!$D$2:$D$500, A43, '01_MASTER_DATABASE'!$G$2:$G$500, "*Cửa sổ*") | E43: =COUNTIFS('01_MASTER_DATABASE'!$D$2:$D$500, A43, '01_MASTER_DATABASE'!$B$2:$B$500, "*Slim*") | F43: =COUNTIFS('01_MASTER_DATABASE'!$D$2:$D$500, A43, '01_MASTER_DATABASE'!$B$2:$B$500, "*Thermal*") + COUNTIFS('01_MASTER_DATABASE'!$D$2:$D$500, A43, '01_MASTER_DATABASE'!$B$2:$B$500, "*cầu*") | G43: =COUNTIFS('01_MASTER_DATABASE'!$D$2:$D$500, A43, '01_MASTER_DATABASE'!$G$2:$G$500, "*mặt dựng*") + COUNTIFS('01_MASTER_DATABASE'!$D$2:$D$500, A43, '01_MASTER_DATABASE'!$G$2:$G$500, "*vách*") | H43: =COUNTIFS('01_MASTER_DATABASE'!$D$2:$D$500, A43, '01_MASTER_DATABASE'!$G$2:$G$500, "*lan can*")

Sheet 03_SO SÁNH PHÂN KHÚC
A1: PHÂN TÍCH HỆ CỬA THEO PHÂN KHÚC THƯƠNG HIỆU
A4: Hãng | B4: Phổ Thông / Tiết Kiệm | C4: Tầm Trung | D4: Cao Cấp rãnh C | E4: Luxury / Siêu Cao Cấp
A5: Civro | B5: =COUNTIFS('01_MASTER_DATABASE'!$D$2:$D$500, A5, '01_MASTER_DATABASE'!$B$2:$B$500, "*Phổ thông*") + COUNTIFS('01_MASTER_DATABASE'!$D$2:$D$500, A5, '01_MASTER_DATABASE'!$B$2:$B$500, "*Vát cạnh*") + COUNTIFS('01_MASTER_DATABASE'!$D$2:$D$500, A5, '01_MASTER_DATABASE'!$B$2:$B$500, "*nhựa*") | C5: =COUNTIFS('01_MASTER_DATABASE'!$D$2:$D$500, A5, '01_MASTER_DATABASE'!$B$2:$B$500, "*Tầm trung*") + COUNTIFS('01_MASTER_DATABASE'!$D$2:$D$500, A5, '01_MASTER_DATABASE'!$B$2:$B$500, "*sản xuất*") | D5: =COUNTIFS('01_MASTER_DATABASE'!$D$2:$D$500, A5, '01_MASTER_DATABASE'!$B$2:$B$500, "*Cao cấp*") + COUNTIFS('01_MASTER_DATABASE'!$D$2:$D$500, A5, '01_MASTER_DATABASE'!$B$2:$B$500, "*Rãnh C*") | E5: =COUNTIFS('01_MASTER_DATABASE'!$D$2:$D$500, A5, '01_MASTER_DATABASE'!$B$2:$B$500, "*Luxury*") + COUNTIFS('01_MASTER_DATABASE'!$D$2:$D$500, A5, '01_MASTER_DATABASE'!$B$2:$B$500, "*Cầu cách nhiệt*")
A6: Civro/Maxpro/Soco | B6: =COUNTIFS('01_MASTER_DATABASE'!$D$2:$D$500, A6, '01_MASTER_DATABASE'!$B$2:$B$500, "*Phổ thông*") + COUNTIFS('01_MASTER_DATABASE'!$D$2:$D$500, A6, '01_MASTER_DATABASE'!$B$2:$B$500, "*Vát cạnh*") + COUNTIFS('01_MASTER_DATABASE'!$D$2:$D$500, A6, '01_MASTER_DATABASE'!$B$2:$B$500, "*nhựa*") | C6: =COUNTIFS('01_MASTER_DATABASE'!$D$2:$D$500, A6, '01_MASTER_DATABASE'!$B$2:$B$500, "*Tầm trung*") + COUNTIFS('01_MASTER_DATABASE'!$D$2:$D$500, A6, '01_MASTER_DATABASE'!$B$2:$B$500, "*sản xuất*") | D6: =COUNTIFS('01_MASTER_DATABASE'!$D$2:$D$500, A6, '01_MASTER_DATABASE'!$B$2:$B$500, "*Cao cấp*") + COUNTIFS('01_MASTER_DATABASE'!$D$2:$D$500, A6, '01_MASTER_DATABASE'!$B$2:$B$500, "*Rãnh C*") | E6: =COUNTIFS('01_MASTER_DATABASE'!$D$2:$D$500, A6, '01_MASTER_DATABASE'!$B$2:$B$500, "*Luxury*") + COUNTIFS('01_MASTER_DATABASE'!$D$2:$D$500, A6, '01_MASTER_DATABASE'!$B$2:$B$500, "*Cầu cách nhiệt*")
A7: Civro/Owin/Local | B7: =COUNTIFS('01_MASTER_DATABASE'!$D$2:$D$500, A7, '01_MASTER_DATABASE'!$B$2:$B$500, "*Phổ thông*") + COUNTIFS('01_MASTER_DATABASE'!$D$2:$D$500, A7, '01_MASTER_DATABASE'!$B$2:$B$500, "*Vát cạnh*") + COUNTIFS('01_MASTER_DATABASE'!$D$2:$D$500, A7, '01_MASTER_DATABASE'!$B$2:$B$500, "*nhựa*") | C7: =COUNTIFS('01_MASTER_DATABASE'!$D$2:$D$500, A7, '01_MASTER_DATABASE'!$B$2:$B$500, "*Tầm trung*") + COUNTIFS('01_MASTER_DATABASE'!$D$2:$D$500, A7, '01_MASTER_DATABASE'!$B$2:$B$500, "*sản xuất*") | D7: =COUNTIFS('01_MASTER_DATABASE'!$D$2:$D$500, A7, '01_MASTER_DATABASE'!$B$2:$B$500, "*Cao cấp*") + COUNTIFS('01_MASTER_DATABASE'!$D$2:$D$500, A7, '01_MASTER_DATABASE'!$B$2:$B$500, "*Rãnh C*") | E7: =COUNTIFS('01_MASTER_DATABASE'!$D$2:$D$500, A7, '01_MASTER_DATABASE'!$B$2:$B$500, "*Luxury*") + COUNTIFS('01_MASTER_DATABASE'!$D$2:$D$500, A7, '01_MASTER_DATABASE'!$B$2:$B$500, "*Cầu cách nhiệt*")
A8: Civro/PAG/Schüco | B8: =COUNTIFS('01_MASTER_DATABASE'!$D$2:$D$500, A8, '01_MASTER_DATABASE'!$B$2:$B$500, "*Phổ thông*") + COUNTIFS('01_MASTER_DATABASE'!$D$2:$D$500, A8, '01_MASTER_DATABASE'!$B$2:$B$500, "*Vát cạnh*") + COUNTIFS('01_MASTER_DATABASE'!$D$2:$D$500, A8, '01_MASTER_DATABASE'!$B$2:$B$500, "*nhựa*") | C8: =COUNTIFS('01_MASTER_DATABASE'!$D$2:$D$500, A8, '01_MASTER_DATABASE'!$B$2:$B$500, "*Tầm trung*") + COUNTIFS('01_MASTER_DATABASE'!$D$2:$D$500, A8, '01_MASTER_DATABASE'!$B$2:$B$500, "*sản xuất*") | D8: =COUNTIFS('01_MASTER_DATABASE'!$D$2:$D$500, A8, '01_MASTER_DATABASE'!$B$2:$B$500, "*Cao cấp*") + COUNTIFS('01_MASTER_DATABASE'!$D$2:$D$500, A8, '01_MASTER_DATABASE'!$B$2:$B$500, "*Rãnh C*") | E8: =COUNTIFS('01_MASTER_DATABASE'!$D$2:$D$500, A8, '01_MASTER_DATABASE'!$B$2:$B$500, "*Luxury*") + COUNTIFS('01_MASTER_DATABASE'!$D$2:$D$500, A8, '01_MASTER_DATABASE'!$B$2:$B$500, "*Cầu cách nhiệt*")
A9: Các hãng | B9: =COUNTIFS('01_MASTER_DATABASE'!$D$2:$D$500, A9, '01_MASTER_DATABASE'!$B$2:$B$500, "*Phổ thông*") + COUNTIFS('01_MASTER_DATABASE'!$D$2:$D$500, A9, '01_MASTER_DATABASE'!$B$2:$B$500, "*Vát cạnh*") + COUNTIFS('01_MASTER_DATABASE'!$D$2:$D$500, A9, '01_MASTER_DATABASE'!$B$2:$B$500, "*nhựa*") | C9: =COUNTIFS('01_MASTER_DATABASE'!$D$2:$D$500, A9, '01_MASTER_DATABASE'!$B$2:$B$500, "*Tầm trung*") + COUNTIFS('01_MASTER_DATABASE'!$D$2:$D$500, A9, '01_MASTER_DATABASE'!$B$2:$B$500, "*sản xuất*") | D9: =COUNTIFS('01_MASTER_DATABASE'!$D$2:$D$500, A9, '01_MASTER_DATABASE'!$B$2:$B$500, "*Cao cấp*") + COUNTIFS('01_MASTER_DATABASE'!$D$2:$D$500, A9, '01_MASTER_DATABASE'!$B$2:$B$500, "*Rãnh C*") | E9: =COUNTIFS('01_MASTER_DATABASE'!$D$2:$D$500, A9, '01_MASTER_DATABASE'!$B$2:$B$500, "*Luxury*") + COUNTIFS('01_MASTER_DATABASE'!$D$2:$D$500, A9, '01_MASTER_DATABASE'!$B$2:$B$500, "*Cầu cách nhiệt*")
A10: Dorma/Besam/Local | B10: =COUNTIFS('01_MASTER_DATABASE'!$D$2:$D$500, A10, '01_MASTER_DATABASE'!$B$2:$B$500, "*Phổ thông*") + COUNTIFS('01_MASTER_DATABASE'!$D$2:$D$500, A10, '01_MASTER_DATABASE'!$B$2:$B$500, "*Vát cạnh*") + COUNTIFS('01_MASTER_DATABASE'!$D$2:$D$500, A10, '01_MASTER_DATABASE'!$B$2:$B$500, "*nhựa*") | C10: =COUNTIFS('01_MASTER_DATABASE'!$D$2:$D$500, A10, '01_MASTER_DATABASE'!$B$2:$B$500, "*Tầm trung*") + COUNTIFS('01_MASTER_DATABASE'!$D$2:$D$500, A10, '01_MASTER_DATABASE'!$B$2:$B$500, "*sản xuất*") | D10: =COUNTIFS('01_MASTER_DATABASE'!$D$2:$D$500, A10, '01_MASTER_DATABASE'!$B$2:$B$500, "*Cao cấp*") + COUNTIFS('01_MASTER_DATABASE'!$D$2:$D$500, A10, '01_MASTER_DATABASE'!$B$2:$B$500, "*Rãnh C*") | E10: =COUNTIFS('01_MASTER_DATABASE'!$D$2:$D$500, A10, '01_MASTER_DATABASE'!$B$2:$B$500, "*Luxury*") + COUNTIFS('01_MASTER_DATABASE'!$D$2:$D$500, A10, '01_MASTER_DATABASE'!$B$2:$B$500, "*Cầu cách nhiệt*")
A11: EuroVN | B11: =COUNTIFS('01_MASTER_DATABASE'!$D$2:$D$500, A11, '01_MASTER_DATABASE'!$B$2:$B$500, "*Phổ thông*") + COUNTIFS('01_MASTER_DATABASE'!$D$2:$D$500, A11, '01_MASTER_DATABASE'!$B$2:$B$500, "*Vát cạnh*") + COUNTIFS('01_MASTER_DATABASE'!$D$2:$D$500, A11, '01_MASTER_DATABASE'!$B$2:$B$500, "*nhựa*") | C11: =COUNTIFS('01_MASTER_DATABASE'!$D$2:$D$500, A11, '01_MASTER_DATABASE'!$B$2:$B$500, "*Tầm trung*") + COUNTIFS('01_MASTER_DATABASE'!$D$2:$D$500, A11, '01_MASTER_DATABASE'!$B$2:$B$500, "*sản xuất*") | D11: =COUNTIFS('01_MASTER_DATABASE'!$D$2:$D$500, A11, '01_MASTER_DATABASE'!$B$2:$B$500, "*Cao cấp*") + COUNTIFS('01_MASTER_DATABASE'!$D$2:$D$500, A11, '01_MASTER_DATABASE'!$B$2:$B$500, "*Rãnh C*") | E11: =COUNTIFS('01_MASTER_DATABASE'!$D$2:$D$500, A11, '01_MASTER_DATABASE'!$B$2:$B$500, "*Luxury*") + COUNTIFS('01_MASTER_DATABASE'!$D$2:$D$500, A11, '01_MASTER_DATABASE'!$B$2:$B$500, "*Cầu cách nhiệt*")
A12: Eurowindow | B12: =COUNTIFS('01_MASTER_DATABASE'!$D$2:$D$500, A12, '01_MASTER_DATABASE'!$B$2:$B$500, "*Phổ thông*") + COUNTIFS('01_MASTER_DATABASE'!$D$2:$D$500, A12, '01_MASTER_DATABASE'!$B$2:$B$500, "*Vát cạnh*") + COUNTIFS('01_MASTER_DATABASE'!$D$2:$D$500, A12, '01_MASTER_DATABASE'!$B$2:$B$500, "*nhựa*") | C12: =COUNTIFS('01_MASTER_DATABASE'!$D$2:$D$500, A12, '01_MASTER_DATABASE'!$B$2:$B$500, "*Tầm trung*") + COUNTIFS('01_MASTER_DATABASE'!$D$2:$D$500, A12, '01_MASTER_DATABASE'!$B$2:$B$500, "*sản xuất*") | D12: =COUNTIFS('01_MASTER_DATABASE'!$D$2:$D$500, A12, '01_MASTER_DATABASE'!$B$2:$B$500, "*Cao cấp*") + COUNTIFS('01_MASTER_DATABASE'!$D$2:$D$500, A12, '01_MASTER_DATABASE'!$B$2:$B$500, "*Rãnh C*") | E12: =COUNTIFS('01_MASTER_DATABASE'!$D$2:$D$500, A12, '01_MASTER_DATABASE'!$B$2:$B$500, "*Luxury*") + COUNTIFS('01_MASTER_DATABASE'!$D$2:$D$500, A12, '01_MASTER_DATABASE'!$B$2:$B$500, "*Cầu cách nhiệt*")
A13: Hondalex | B13: =COUNTIFS('01_MASTER_DATABASE'!$D$2:$D$500, A13, '01_MASTER_DATABASE'!$B$2:$B$500, "*Phổ thông*") + COUNTIFS('01_MASTER_DATABASE'!$D$2:$D$500, A13, '01_MASTER_DATABASE'!$B$2:$B$500, "*Vát cạnh*") + COUNTIFS('01_MASTER_DATABASE'!$D$2:$D$500, A13, '01_MASTER_DATABASE'!$B$2:$B$500, "*nhựa*") | C13: =COUNTIFS('01_MASTER_DATABASE'!$D$2:$D$500, A13, '01_MASTER_DATABASE'!$B$2:$B$500, "*Tầm trung*") + COUNTIFS('01_MASTER_DATABASE'!$D$2:$D$500, A13, '01_MASTER_DATABASE'!$B$2:$B$500, "*sản xuất*") | D13: =COUNTIFS('01_MASTER_DATABASE'!$D$2:$D$500, A13, '01_MASTER_DATABASE'!$B$2:$B$500, "*Cao cấp*") + COUNTIFS('01_MASTER_DATABASE'!$D$2:$D$500, A13, '01_MASTER_DATABASE'!$B$2:$B$500, "*Rãnh C*") | E13: =COUNTIFS('01_MASTER_DATABASE'!$D$2:$D$500, A13, '01_MASTER_DATABASE'!$B$2:$B$500, "*Luxury*") + COUNTIFS('01_MASTER_DATABASE'!$D$2:$D$500, A13, '01_MASTER_DATABASE'!$B$2:$B$500, "*Cầu cách nhiệt*")
A14: Hệ PCCC | B14: =COUNTIFS('01_MASTER_DATABASE'!$D$2:$D$500, A14, '01_MASTER_DATABASE'!$B$2:$B$500, "*Phổ thông*") + COUNTIFS('01_MASTER_DATABASE'!$D$2:$D$500, A14, '01_MASTER_DATABASE'!$B$2:$B$500, "*Vát cạnh*") + COUNTIFS('01_MASTER_DATABASE'!$D$2:$D$500, A14, '01_MASTER_DATABASE'!$B$2:$B$500, "*nhựa*") | C14: =COUNTIFS('01_MASTER_DATABASE'!$D$2:$D$500, A14, '01_MASTER_DATABASE'!$B$2:$B$500, "*Tầm trung*") + COUNTIFS('01_MASTER_DATABASE'!$D$2:$D$500, A14, '01_MASTER_DATABASE'!$B$2:$B$500, "*sản xuất*") | D14: =COUNTIFS('01_MASTER_DATABASE'!$D$2:$D$500, A14, '01_MASTER_DATABASE'!$B$2:$B$500, "*Cao cấp*") + COUNTIFS('01_MASTER_DATABASE'!$D$2:$D$500, A14, '01_MASTER_DATABASE'!$B$2:$B$500, "*Rãnh C*") | E14: =COUNTIFS('01_MASTER_DATABASE'!$D$2:$D$500, A14, '01_MASTER_DATABASE'!$B$2:$B$500, "*Luxury*") + COUNTIFS('01_MASTER_DATABASE'!$D$2:$D$500, A14, '01_MASTER_DATABASE'!$B$2:$B$500, "*Cầu cách nhiệt*")
A15: Hệ Smart | B15: =COUNTIFS('01_MASTER_DATABASE'!$D$2:$D$500, A15, '01_MASTER_DATABASE'!$B$2:$B$500, "*Phổ thông*") + COUNTIFS('01_MASTER_DATABASE'!$D$2:$D$500, A15, '01_MASTER_DATABASE'!$B$2:$B$500, "*Vát cạnh*") + COUNTIFS('01_MASTER_DATABASE'!$D$2:$D$500, A15, '01_MASTER_DATABASE'!$B$2:$B$500, "*nhựa*") | C15: =COUNTIFS('01_MASTER_DATABASE'!$D$2:$D$500, A15, '01_MASTER_DATABASE'!$B$2:$B$500, "*Tầm trung*") + COUNTIFS('01_MASTER_DATABASE'!$D$2:$D$500, A15, '01_MASTER_DATABASE'!$B$2:$B$500, "*sản xuất*") | D15: =COUNTIFS('01_MASTER_DATABASE'!$D$2:$D$500, A15, '01_MASTER_DATABASE'!$B$2:$B$500, "*Cao cấp*") + COUNTIFS('01_MASTER_DATABASE'!$D$2:$D$500, A15, '01_MASTER_DATABASE'!$B$2:$B$500, "*Rãnh C*") | E15: =COUNTIFS('01_MASTER_DATABASE'!$D$2:$D$500, A15, '01_MASTER_DATABASE'!$B$2:$B$500, "*Luxury*") + COUNTIFS('01_MASTER_DATABASE'!$D$2:$D$500, A15, '01_MASTER_DATABASE'!$B$2:$B$500, "*Cầu cách nhiệt*")
A16: Hệ chuyên dụng | B16: =COUNTIFS('01_MASTER_DATABASE'!$D$2:$D$500, A16, '01_MASTER_DATABASE'!$B$2:$B$500, "*Phổ thông*") + COUNTIFS('01_MASTER_DATABASE'!$D$2:$D$500, A16, '01_MASTER_DATABASE'!$B$2:$B$500, "*Vát cạnh*") + COUNTIFS('01_MASTER_DATABASE'!$D$2:$D$500, A16, '01_MASTER_DATABASE'!$B$2:$B$500, "*nhựa*") | C16: =COUNTIFS('01_MASTER_DATABASE'!$D$2:$D$500, A16, '01_MASTER_DATABASE'!$B$2:$B$500, "*Tầm trung*") + COUNTIFS('01_MASTER_DATABASE'!$D$2:$D$500, A16, '01_MASTER_DATABASE'!$B$2:$B$500, "*sản xuất*") | D16: =COUNTIFS('01_MASTER_DATABASE'!$D$2:$D$500, A16, '01_MASTER_DATABASE'!$B$2:$B$500, "*Cao cấp*") + COUNTIFS('01_MASTER_DATABASE'!$D$2:$D$500, A16, '01_MASTER_DATABASE'!$B$2:$B$500, "*Rãnh C*") | E16: =COUNTIFS('01_MASTER_DATABASE'!$D$2:$D$500, A16, '01_MASTER_DATABASE'!$B$2:$B$500, "*Luxury*") + COUNTIFS('01_MASTER_DATABASE'!$D$2:$D$500, A16, '01_MASTER_DATABASE'!$B$2:$B$500, "*Cầu cách nhiệt*")
... A43: Yangli | B43: =COUNTIFS('01_MASTER_DATABASE'!$D$2:$D$500, A43, '01_MASTER_DATABASE'!$B$2:$B$500, "*Phổ thông*") + COUNTIFS('01_MASTER_DATABASE'!$D$2:$D$500, A43, '01_MASTER_DATABASE'!$B$2:$B$500, "*Vát cạnh*") + COUNTIFS('01_MASTER_DATABASE'!$D$2:$D$500, A43, '01_MASTER_DATABASE'!$B$2:$B$500, "*nhựa*") | C43: =COUNTIFS('01_MASTER_DATABASE'!$D$2:$D$500, A43, '01_MASTER_DATABASE'!$B$2:$B$500, "*Tầm trung*") + COUNTIFS('01_MASTER_DATABASE'!$D$2:$D$500, A43, '01_MASTER_DATABASE'!$B$2:$B$500, "*sản xuất*") | D43: =COUNTIFS('01_MASTER_DATABASE'!$D$2:$D$500, A43, '01_MASTER_DATABASE'!$B$2:$B$500, "*Cao cấp*") + COUNTIFS('01_MASTER_DATABASE'!$D$2:$D$500, A43, '01_MASTER_DATABASE'!$B$2:$B$500, "*Rãnh C*") | E43: =COUNTIFS('01_MASTER_DATABASE'!$D$2:$D$500, A43, '01_MASTER_DATABASE'!$B$2:$B$500, "*Luxury*") + COUNTIFS('01_MASTER_DATABASE'!$D$2:$D$500, A43, '01_MASTER_DATABASE'!$B$2:$B$500, "*Cầu cách nhiệt*")

Sheet 04_SO SÁNH LOẠI CỬA
A1: PHÂN LOẠI CỬA THEO THỂ LOẠI (CỬA ĐI, SỔ, VÁCH, MÁI...)
A4: Hãng | B4: Cửa Đi | C4: Cửa Sổ | D4: Vách Ngăn | E4: Mặt Dựng Vách Kính | F4: Lan Can Kính | G4: Mái Kính Cường Lực | H4: Khác
A5: Civro | B5: =COUNTIFS('01_MASTER_DATABASE'!$D$2:$D$500, A5, '01_MASTER_DATABASE'!$G$2:$G$500, "*Cửa đi*") | C5: =COUNTIFS('01_MASTER_DATABASE'!$D$2:$D$500, A5, '01_MASTER_DATABASE'!$G$2:$G$500, "*Cửa sổ*") | D5: =COUNTIFS('01_MASTER_DATABASE'!$D$2:$D$500, A5, '01_MASTER_DATABASE'!$G$2:$G$500, "*vách ngăn*") | E5: =COUNTIFS('01_MASTER_DATABASE'!$D$2:$D$500, A5, '01_MASTER_DATABASE'!$G$2:$G$500, "*mặt dựng*") | F5: =COUNTIFS('01_MASTER_DATABASE'!$D$2:$D$500, A5, '01_MASTER_DATABASE'!$G$2:$G$500, "*lan can*") | G5: =COUNTIFS('01_MASTER_DATABASE'!$D$2:$D$500, A5, '01_MASTER_DATABASE'!$G$2:$G$500, "*mái kính*") | H5: =COUNTIF('01_MASTER_DATABASE'!$D$2:$D$500, A5) - (B5+C5+D5+E5+F5+G5)
A6: Civro/Maxpro/Soco | B6: =COUNTIFS('01_MASTER_DATABASE'!$D$2:$D$500, A6, '01_MASTER_DATABASE'!$G$2:$G$500, "*Cửa đi*") | C6: =COUNTIFS('01_MASTER_DATABASE'!$D$2:$D$500, A6, '01_MASTER_DATABASE'!$G$2:$G$500, "*Cửa sổ*") | D6: =COUNTIFS('01_MASTER_DATABASE'!$D$2:$D$500, A6, '01_MASTER_DATABASE'!$G$2:$G$500, "*vách ngăn*") | E6: =COUNTIFS('01_MASTER_DATABASE'!$D$2:$D$500, A6, '01_MASTER_DATABASE'!$G$2:$G$500, "*mặt dựng*") | F6: =COUNTIFS('01_MASTER_DATABASE'!$D$2:$D$500, A6, '01_MASTER_DATABASE'!$G$2:$G$500, "*lan can*") | G6: =COUNTIFS('01_MASTER_DATABASE'!$D$2:$D$500, A6, '01_MASTER_DATABASE'!$G$2:$G$500, "*mái kính*") | H6: =COUNTIF('01_MASTER_DATABASE'!$D$2:$D$500, A6) - (B6+C6+D6+E6+F6+G6)
A7: Civro/Owin/Local | B7: =COUNTIFS('01_MASTER_DATABASE'!$D$2:$D$500, A7, '01_MASTER_DATABASE'!$G$2:$G$500, "*Cửa đi*") | C7: =COUNTIFS('01_MASTER_DATABASE'!$D$2:$D$500, A7, '01_MASTER_DATABASE'!$G$2:$G$500, "*Cửa sổ*") | D7: =COUNTIFS('01_MASTER_DATABASE'!$D$2:$D$500, A7, '01_MASTER_DATABASE'!$G$2:$G$500, "*vách ngăn*") | E7: =COUNTIFS('01_MASTER_DATABASE'!$D$2:$D$500, A7, '01_MASTER_DATABASE'!$G$2:$G$500, "*mặt dựng*") | F7: =COUNTIFS('01_MASTER_DATABASE'!$D$2:$D$500, A7, '01_MASTER_DATABASE'!$G$2:$G$500, "*lan can*") | G7: =COUNTIFS('01_MASTER_DATABASE'!$D$2:$D$500, A7, '01_MASTER_DATABASE'!$G$2:$G$500, "*mái kính*") | H7: =COUNTIF('01_MASTER_DATABASE'!$D$2:$D$500, A7) - (B7+C7+D7+E7+F7+G7)
A8: Civro/PAG/Schüco | B8: =COUNTIFS('01_MASTER_DATABASE'!$D$2:$D$500, A8, '01_MASTER_DATABASE'!$G$2:$G$500, "*Cửa đi*") | C8: =COUNTIFS('01_MASTER_DATABASE'!$D$2:$D$500, A8, '01_MASTER_DATABASE'!$G$2:$G$500, "*Cửa sổ*") | D8: =COUNTIFS('01_MASTER_DATABASE'!$D$2:$D$500, A8, '01_MASTER_DATABASE'!$G$2:$G$500, "*vách ngăn*") | E8: =COUNTIFS('01_MASTER_DATABASE'!$D$2:$D$500, A8, '01_MASTER_DATABASE'!$G$2:$G$500, "*mặt dựng*") | F8: =COUNTIFS('01_MASTER_DATABASE'!$D$2:$D$500, A8, '01_MASTER_DATABASE'!$G$2:$G$500, "*lan can*") | G8: =COUNTIFS('01_MASTER_DATABASE'!$D$2:$D$500, A8, '01_MASTER_DATABASE'!$G$2:$G$500, "*mái kính*") | H8: =COUNTIF('01_MASTER_DATABASE'!$D$2:$D$500, A8) - (B8+C8+D8+E8+F8+G8)
A9: Các hãng | B9: =COUNTIFS('01_MASTER_DATABASE'!$D$2:$D$500, A9, '01_MASTER_DATABASE'!$G$2:$G$500, "*Cửa đi*") | C9: =COUNTIFS('01_MASTER_DATABASE'!$D$2:$D$500, A9, '01_MASTER_DATABASE'!$G$2:$G$500, "*Cửa sổ*") | D9: =COUNTIFS('01_MASTER_DATABASE'!$D$2:$D$500, A9, '01_MASTER_DATABASE'!$G$2:$G$500, "*vách ngăn*") | E9: =COUNTIFS('01_MASTER_DATABASE'!$D$2:$D$500, A9, '01_MASTER_DATABASE'!$G$2:$G$500, "*mặt dựng*") | F9: =COUNTIFS('01_MASTER_DATABASE'!$D$2:$D$500, A9, '01_MASTER_DATABASE'!$G$2:$G$500, "*lan can*") | G9: =COUNTIFS('01_MASTER_DATABASE'!$D$2:$D$500, A9, '01_MASTER_DATABASE'!$G$2:$G$500, "*mái kính*") | H9: =COUNTIF('01_MASTER_DATABASE'!$D$2:$D$500, A9) - (B9+C9+D9+E9+F9+G9)
A10: Dorma/Besam/Local | B10: =COUNTIFS('01_MASTER_DATABASE'!$D$2:$D$500, A10, '01_MASTER_DATABASE'!$G$2:$G$500, "*Cửa đi*") | C10: =COUNTIFS('01_MASTER_DATABASE'!$D$2:$D$500, A10, '01_MASTER_DATABASE'!$G$2:$G$500, "*Cửa sổ*") | D10: =COUNTIFS('01_MASTER_DATABASE'!$D$2:$D$500, A10, '01_MASTER_DATABASE'!$G$2:$G$500, "*vách ngăn*") | E10: =COUNTIFS('01_MASTER_DATABASE'!$D$2:$D$500, A10, '01_MASTER_DATABASE'!$G$2:$G$500, "*mặt dựng*") | F10: =COUNTIFS('01_MASTER_DATABASE'!$D$2:$D$500, A10, '01_MASTER_DATABASE'!$G$2:$G$500, "*lan can*") | G10: =COUNTIFS('01_MASTER_DATABASE'!$D$2:$D$500, A10, '01_MASTER_DATABASE'!$G$2:$G$500, "*mái kính*") | H10: =COUNTIF('01_MASTER_DATABASE'!$D$2:$D$500, A10) - (B10+C10+D10+E10+F10+G10)
A11: EuroVN | B11: =COUNTIFS('01_MASTER_DATABASE'!$D$2:$D$500, A11, '01_MASTER_DATABASE'!$G$2:$G$500, "*Cửa đi*") | C11: =COUNTIFS('01_MASTER_DATABASE'!$D$2:$D$500, A11, '01_MASTER_DATABASE'!$G$2:$G$500, "*Cửa sổ*") | D11: =COUNTIFS('01_MASTER_DATABASE'!$D$2:$D$500, A11, '01_MASTER_DATABASE'!$G$2:$G$500, "*vách ngăn*") | E11: =COUNTIFS('01_MASTER_DATABASE'!$D$2:$D$500, A11, '01_MASTER_DATABASE'!$G$2:$G$500, "*mặt dựng*") | F11: =COUNTIFS('01_MASTER_DATABASE'!$D$2:$D$500, A11, '01_MASTER_DATABASE'!$G$2:$G$500, "*lan can*") | G11: =COUNTIFS('01_MASTER_DATABASE'!$D$2:$D$500, A11, '01_MASTER_DATABASE'!$G$2:$G$500, "*mái kính*") | H11: =COUNTIF('01_MASTER_DATABASE'!$D$2:$D$500, A11) - (B11+C11+D11+E11+F11+G11)
A12: Eurowindow | B12: =COUNTIFS('01_MASTER_DATABASE'!$D$2:$D$500, A12, '01_MASTER_DATABASE'!$G$2:$G$500, "*Cửa đi*") | C12: =COUNTIFS('01_MASTER_DATABASE'!$D$2:$D$500, A12, '01_MASTER_DATABASE'!$G$2:$G$500, "*Cửa sổ*") | D12: =COUNTIFS('01_MASTER_DATABASE'!$D$2:$D$500, A12, '01_MASTER_DATABASE'!$G$2:$G$500, "*vách ngăn*") | E12: =COUNTIFS('01_MASTER_DATABASE'!$D$2:$D$500, A12, '01_MASTER_DATABASE'!$G$2:$G$500, "*mặt dựng*") | F12: =COUNTIFS('01_MASTER_DATABASE'!$D$2:$D$500, A12, '01_MASTER_DATABASE'!$G$2:$G$500, "*lan can*") | G12: =COUNTIFS('01_MASTER_DATABASE'!$D$2:$D$500, A12, '01_MASTER_DATABASE'!$G$2:$G$500, "*mái kính*") | H12: =COUNTIF('01_MASTER_DATABASE'!$D$2:$D$500, A12) - (B12+C12+D12+E12+F12+G12)
A13: Hondalex | B13: =COUNTIFS('01_MASTER_DATABASE'!$D$2:$D$500, A13, '01_MASTER_DATABASE'!$G$2:$G$500, "*Cửa đi*") | C13: =COUNTIFS('01_MASTER_DATABASE'!$D$2:$D$500, A13, '01_MASTER_DATABASE'!$G$2:$G$500, "*Cửa sổ*") | D13: =COUNTIFS('01_MASTER_DATABASE'!$D$2:$D$500, A13, '01_MASTER_DATABASE'!$G$2:$G$500, "*vách ngăn*") | E13: =COUNTIFS('01_MASTER_DATABASE'!$D$2:$D$500, A13, '01_MASTER_DATABASE'!$G$2:$G$500, "*mặt dựng*") | F13: =COUNTIFS('01_MASTER_DATABASE'!$D$2:$D$500, A13, '01_MASTER_DATABASE'!$G$2:$G$500, "*lan can*") | G13: =COUNTIFS('01_MASTER_DATABASE'!$D$2:$D$500, A13, '01_MASTER_DATABASE'!$G$2:$G$500, "*mái kính*") | H13: =COUNTIF('01_MASTER_DATABASE'!$D$2:$D$500, A13) - (B13+C13+D13+E13+F13+G13)
A14: Hệ PCCC | B14: =COUNTIFS('01_MASTER_DATABASE'!$D$2:$D$500, A14, '01_MASTER_DATABASE'!$G$2:$G$500, "*Cửa đi*") | C14: =COUNTIFS('01_MASTER_DATABASE'!$D$2:$D$500, A14, '01_MASTER_DATABASE'!$G$2:$G$500, "*Cửa sổ*") | D14: =COUNTIFS('01_MASTER_DATABASE'!$D$2:$D$500, A14, '01_MASTER_DATABASE'!$G$2:$G$500, "*vách ngăn*") | E14: =COUNTIFS('01_MASTER_DATABASE'!$D$2:$D$500, A14, '01_MASTER_DATABASE'!$G$2:$G$500, "*mặt dựng*") | F14: =COUNTIFS('01_MASTER_DATABASE'!$D$2:$D$500, A14, '01_MASTER_DATABASE'!$G$2:$G$500, "*lan can*") | G14: =COUNTIFS('01_MASTER_DATABASE'!$D$2:$D$500, A14, '01_MASTER_DATABASE'!$G$2:$G$500, "*mái kính*") | H14: =COUNTIF('01_MASTER_DATABASE'!$D$2:$D$500, A14) - (B14+C14+D14+E14+F14+G14)
A15: Hệ Smart | B15: =COUNTIFS('01_MASTER_DATABASE'!$D$2:$D$500, A15, '01_MASTER_DATABASE'!$G$2:$G$500, "*Cửa đi*") | C15: =COUNTIFS('01_MASTER_DATABASE'!$D$2:$D$500, A15, '01_MASTER_DATABASE'!$G$2:$G$500, "*Cửa sổ*") | D15: =COUNTIFS('01_MASTER_DATABASE'!$D$2:$D$500, A15, '01_MASTER_DATABASE'!$G$2:$G$500, "*vách ngăn*") | E15: =COUNTIFS('01_MASTER_DATABASE'!$D$2:$D$500, A15, '01_MASTER_DATABASE'!$G$2:$G$500, "*mặt dựng*") | F15: =COUNTIFS('01_MASTER_DATABASE'!$D$2:$D$500, A15, '01_MASTER_DATABASE'!$G$2:$G$500, "*lan can*") | G15: =COUNTIFS('01_MASTER_DATABASE'!$D$2:$D$500, A15, '01_MASTER_DATABASE'!$G$2:$G$500, "*mái kính*") | H15: =COUNTIF('01_MASTER_DATABASE'!$D$2:$D$500, A15) - (B15+C15+D15+E15+F15+G15)
A16: Hệ chuyên dụng | B16: =COUNTIFS('01_MASTER_DATABASE'!$D$2:$D$500, A16, '01_MASTER_DATABASE'!$G$2:$G$500, "*Cửa đi*") | C16: =COUNTIFS('01_MASTER_DATABASE'!$D$2:$D$500, A16, '01_MASTER_DATABASE'!$G$2:$G$500, "*Cửa sổ*") | D16: =COUNTIFS('01_MASTER_DATABASE'!$D$2:$D$500, A16, '01_MASTER_DATABASE'!$G$2:$G$500, "*vách ngăn*") | E16: =COUNTIFS('01_MASTER_DATABASE'!$D$2:$D$500, A16, '01_MASTER_DATABASE'!$G$2:$G$500, "*mặt dựng*") | F16: =COUNTIFS('01_MASTER_DATABASE'!$D$2:$D$500, A16, '01_MASTER_DATABASE'!$G$2:$G$500, "*lan can*") | G16: =COUNTIFS('01_MASTER_DATABASE'!$D$2:$D$500, A16, '01_MASTER_DATABASE'!$G$2:$G$500, "*mái kính*") | H16: =COUNTIF('01_MASTER_DATABASE'!$D$2:$D$500, A16) - (B16+C16+D16+E16+F16+G16)
... A43: Yangli | B43: =COUNTIFS('01_MASTER_DATABASE'!$D$2:$D$500, A43, '01_MASTER_DATABASE'!$G$2:$G$500, "*Cửa đi*") | C43: =COUNTIFS('01_MASTER_DATABASE'!$D$2:$D$500, A43, '01_MASTER_DATABASE'!$G$2:$G$500, "*Cửa sổ*") | D43: =COUNTIFS('01_MASTER_DATABASE'!$D$2:$D$500, A43, '01_MASTER_DATABASE'!$G$2:$G$500, "*vách ngăn*") | E43: =COUNTIFS('01_MASTER_DATABASE'!$D$2:$D$500, A43, '01_MASTER_DATABASE'!$G$2:$G$500, "*mặt dựng*") | F43: =COUNTIFS('01_MASTER_DATABASE'!$D$2:$D$500, A43, '01_MASTER_DATABASE'!$G$2:$G$500, "*lan can*") | G43: =COUNTIFS('01_MASTER_DATABASE'!$D$2:$D$500, A43, '01_MASTER_DATABASE'!$G$2:$G$500, "*mái kính*") | H43: =COUNTIF('01_MASTER_DATABASE'!$D$2:$D$500, A43) - (B43+C43+D43+E43+F43+G43)

Sheet 05_SO SÁNH KIỂU MỞ
A1: SO SÁNH CÁC PHƯƠNG ÁN KIỂU MỞ CÁNH CỬA
A4: Hãng | B4: Mở Quay (Casement) | C4: Trượt Lùa (Sliding) | D4: Mở Hất (Awning) | E4: Xếp Trượt (Folding) | F4: Trượt Quay (Slide & Turn) | G4: Pivot / Trục Xoay
